#VRML_SIM R2025a utf8

EXTERNPROTO "https://raw.githubusercontent.com/cyberbotics/webots/R2025a/projects/objects/backgrounds/protos/TexturedBackground.proto"
EXTERNPROTO "https://raw.githubusercontent.com/cyberbotics/webots/R2025a/projects/objects/backgrounds/protos/TexturedBackgroundLight.proto"
EXTERNPROTO "https://raw.githubusercontent.com/cyberbotics/webots/R2025a/projects/objects/floors/protos/RectangleArena.proto"
EXTERNPROTO "https://raw.githubusercontent.com/cyberbotics/webots/R2025a/projects/objects/factory/containers/protos/CardboardBox.proto"

WorldInfo {
  basicTimeStep 20
  contactProperties [
    ContactProperties {
      material1 "frictionless_caster"
      coulombFriction [
        0
      ]
      bounce 0
    }
    ContactProperties {
      coulombFriction [
        0.8
      ]
      bounce 0
    }
  ]
}
Viewpoint {
  orientation -0.3215149706368148 0.7277229862205172 0.6058443521092701 1.2601801720809984
  position -9.26013898504783 -7.484772398703121 13.829485742856866
}
TexturedBackground {
}
TexturedBackgroundLight {
}
RectangleArena {
  floorSize 10 10
  floorTileSize 2 2
}
Robot {
  name "Ros2Supervisor"
  controller "<extern>"
  supervisor TRUE
}
Robot {
  name "rtf_monitor_node"
  controller "<extern>"
  supervisor TRUE
  synchronization FALSE
}
DEF BOX_A CardboardBox {
  translation 0.491226 -0.401389 -0.810787
  rotation 0 1 0 0.261804
}
DEF BOX_B CardboardBox {
  translation 3.48863 3.25366 -0.99
  name "cardboard box(1)"
}
DEF MY_ROBOT Robot {
  translation -4.16 -4.22 0.056
  rotation 0 0 -1 -1.5707996938995747
  children [
    GPS {
    }
    InertialUnit {
      translation -0.08535 0 -0.04
      rotation 1 0 0 3.14159
      name "my_imu"
    }
    Gyro {
      translation -0.085 0 -0.04
      rotation 1 0 0 3.14159
      lookupTable [
        -1000 -1000 0.01
        1000 1000 0.01
      ]
    }
    Accelerometer {
      translation -0.085 0 -0.04
      rotation 1 0 0 3.14159
      lookupTable [
        -1000 -1000 0.01
        1000 1000 0.01
      ]
    }
    Shape {
      appearance DEF white PBRAppearance {
        roughness 1
        metalness 0
      }
      geometry Box {
        size 0.31 0.22 0.08
      }
    }
    HingeJoint {
      jointParameters HingeJointParameters {
        axis 0 1 0
        anchor -0.08535 -0.125 -0.02105
      }
      device [
        RotationalMotor {
          name "joint_br"
          maxVelocity 17.29
          maxTorque 1.2
        }
        PositionSensor {
          name "joint_br_sensor"
          noise 0.02
          resolution 0.05236
        }
      ]
      endPoint Solid {
        translation -0.08535 -0.125 -0.02105
        children [
          Pose {
            rotation 1 0 0 1.5708
            children [
              Shape {
                appearance DEF blue PBRAppearance {
                  baseColor 0 0 1
                  roughness 1
                  metalness 0
                }
                geometry Cylinder {
                  height 0.0255
                  radius 0.0347
                }
              }
            ]
          }
        ]
        name "link_br"
        boundingObject Pose {
          rotation 1 0 0 1.5708
          children [
            Sphere {
              radius 0.0347
            }
          ]
        }
        physics Physics {
          density -1
          mass 0.02355
          centerOfMass [
            0 0 0
          ]
          inertiaMatrix [
            8.354e-05 0.00014178 8.354e-05
            0 0 0
          ]
        }
      }
    }
    HingeJoint {
      jointParameters HingeJointParameters {
        axis 0 1 0
        anchor -0.08535 0.125 -0.02105
      }
      device [
        RotationalMotor {
          name "joint_bl"
          maxVelocity 17.29
          maxTorque 1.2
        }
        PositionSensor {
          name "joint_bl_sensor"
          noise 0.02
          resolution 0.05236
        }
      ]
      endPoint Solid {
        translation -0.08535 0.125 -0.02105
        children [
          Pose {
            rotation 1 0 0 1.5708
            children [
              Shape {
                appearance PBRAppearance {
                  baseColor 0.5 0.5 0.5
                  roughness 1
                  metalness 0
                }
                geometry Cylinder {
                  height 0.0255
                  radius 0.0347
                }
              }
            ]
          }
        ]
        name "link_bl"
        boundingObject Pose {
          rotation 1 0 0 1.5708
          children [
            Sphere {
              radius 0.0347
            }
          ]
        }
        physics Physics {
          density -1
          mass 0.02355
          centerOfMass [
            0 0 0
          ]
          inertiaMatrix [
            8.354e-05 0.00014178 8.354e-05
            0 0 0
          ]
        }
      }
    }
    Solid {
      translation 0.0965 0 -0.048
      children [
        Solid {
          children [
            Shape {
              appearance DEF grey PBRAppearance {
                baseColor 0.5 0.5 0.5
                roughness 1
                metalness 0
              }
              geometry Sphere {
                radius 0.007995
              }
            }
          ]
          name "link_front"
          contactMaterial "frictionless_caster"
          boundingObject Sphere {
            radius 0.007995
          }
          physics Physics {
            density -1
            mass 0.05
            centerOfMass [
              0 0 0
            ]
            inertiaMatrix [
              1e-06 1e-06 1e-06
              0 0 0
            ]
          }
        }
      ]
      name "caster_swivel"
      physics Physics {
        density -1
        mass 0.001
        centerOfMass [
          0 0 0
        ]
        inertiaMatrix [
          1e-06 1e-06 1e-06
          0 0 0
        ]
      }
    }
    Solid {
      translation 0 0 0.04
      children [
        Pose {
          translation 0 0 0.02425
          children [
            Shape {
              appearance DEF dark_grey PBRAppearance {
                baseColor 0.2 0.2 0.2
                roughness 1
                metalness 0
              }
              geometry Cylinder {
                height 0.0485
                radius 0.0125
              }
            }
          ]
        }
        Lidar {
          name "webots_lidar"
          horizontalResolution 360
          fieldOfView 6.28318
          numberOfLayers 1
          minRange 0.12
          maxRange 3.5
          noise 0.03
          resolution 0.015
        }
      ]
      name "lidar_link"
      boundingObject Pose {
        translation 0 0 0.02425
        children [
          Cylinder {
            height 0.0485
            radius 0.0125
          }
        ]
      }
      physics Physics {
        density -1
        mass 0.052
        centerOfMass [
          0 0 0
        ]
        inertiaMatrix [
          4e-06 4e-06 4e-06
          0 0 0
        ]
      }
    }
    Solid {
      translation 0.1595 0 0.00364
      rotation -0.5890625095294486 0.5531823566724958 -0.5890625095294486 2.02114
      children [
        Shape {
          appearance DEF red PBRAppearance {
            baseColor 1 0 0
            roughness 1
            metalness 0
          }
          geometry Box {
            size 0.0045 0.025 0.023
          }
        }
        Pose {
          rotation 0.5773502691896258 -0.5773502691896258 0.5773502691896258 2.09439
          children [
            Camera {
              name "my_webots_camera"
              fieldOfView 1.047
              width 640
              height 480
            }
          ]
        }
      ]
      name "camera_link"
      physics Physics {
        density -1
        mass 0.004
        centerOfMass [
          0 0 0
        ]
        inertiaMatrix [
          3e-07 2e-07 2e-07
          0 0 0
        ]
      }
    }
  ]
  name "robot_a"
  boundingObject Box {
    size 0.31 0.22 0.08
  }
  physics Physics {
    density -1
    mass 1.54074
    centerOfMass [
      0 0 0
    ]
    inertiaMatrix [
      0.007512 0.014051 0.019808
      0 0 0
    ]
  }
  controller "<extern>"
}
