#VRML_SIM R2025a utf8

EXTERNPROTO "https://raw.githubusercontent.com/cyberbotics/webots/R2025a/projects/objects/backgrounds/protos/TexturedBackground.proto"
EXTERNPROTO "https://raw.githubusercontent.com/cyberbotics/webots/R2025a/projects/objects/backgrounds/protos/TexturedBackgroundLight.proto"
EXTERNPROTO "https://raw.githubusercontent.com/cyberbotics/webots/R2025a/projects/objects/floors/protos/RectangleArena.proto"
EXTERNPROTO "https://raw.githubusercontent.com/cyberbotics/webots/R2025a/projects/appearances/protos/CementTiles.proto"
EXTERNPROTO "https://raw.githubusercontent.com/cyberbotics/webots/R2025a/projects/appearances/protos/Copper.proto"
EXTERNPROTO "https://raw.githubusercontent.com/cyberbotics/webots/R2025a/projects/objects/factory/containers/protos/WoodenBox.proto"
EXTERNPROTO "https://raw.githubusercontent.com/cyberbotics/webots/R2025a/projects/objects/apartment_structure/protos/Wall.proto"
EXTERNPROTO "https://raw.githubusercontent.com/cyberbotics/webots/R2025a/projects/objects/factory/conveyors/protos/ConveyorBelt.proto"
EXTERNPROTO "https://raw.githubusercontent.com/cyberbotics/webots/R2025a/projects/objects/factory/fire_extinguisher/protos/FireExtinguisher.proto"
EXTERNPROTO "https://raw.githubusercontent.com/cyberbotics/webots/R2025a/projects/objects/factory/manhole/protos/SquareManhole.proto"
EXTERNPROTO "https://raw.githubusercontent.com/cyberbotics/webots/R2025a/projects/objects/factory/valves/protos/SmallValve.proto"
EXTERNPROTO "https://raw.githubusercontent.com/cyberbotics/webots/R2025a/projects/objects/factory/tools/protos/PlatformCart.proto"
EXTERNPROTO "https://raw.githubusercontent.com/cyberbotics/webots/R2025a/projects/objects/factory/pallet/protos/WoodenPallet.proto"
EXTERNPROTO "https://raw.githubusercontent.com/cyberbotics/webots/R2025a/projects/objects/cabinet/protos/Cabinet.proto"
EXTERNPROTO "https://raw.githubusercontent.com/cyberbotics/webots/R2025a/projects/humans/pedestrian/protos/Pedestrian.proto"
EXTERNPROTO "https://raw.githubusercontent.com/cyberbotics/webots/R2025a/projects/objects/factory/containers/protos/PlasticCrate.proto"

WorldInfo {
  basicTimeStep 20
  contactProperties [
    ContactProperties {
      material1 "frictionless_caster"
      coulombFriction [
        0
      ]
      bounce 0
    }
    ContactProperties {
      coulombFriction [
        0.85
      ]
      bounce 0
    }
  ]
}
Viewpoint {
  orientation -0.028117881927327483 -0.9957711900186149 0.08745925819964769 5.658662578305562
  position -11.959935114823839 2.7549923182278384 9.206479319739937
}
TexturedBackground {
}
TexturedBackgroundLight {
}
RectangleArena {
  floorSize 15 15
  floorAppearance Copper {
  }
  wallAppearance CementTiles {
  }
}
Pedestrian {
  translation -6.38 -1.65 1.27
  shirtColor 1 0.333333 0
  pantsColor 1 0.333333 0
  skinColor 0.333333 0.129412 0.027451
}
Pedestrian {
  translation 2.36 -2.87 1.37
  rotation 0 0 1 1.0472
  name "pedestrian(1)"
  shirtColor 1 0.333333 0
  pantsColor 1 0.333333 0
}
Pedestrian {
  translation -0.734118 5.7176 1.47
  rotation 0 0 1 1.0472
  name "pedestrian(4)"
  shirtColor 1 0.333333 0
  pantsColor 1 0.333333 0
}
Pedestrian {
  translation -4.33 -3.45 1.47
  rotation 0 0 1 -1.8325953071795862
  name "pedestrian(2)"
  shirtColor 1 0.333333 0
  pantsColor 1 0.333333 0
}
Pedestrian {
  translation 0.3 -3.75 1.57
  rotation 0 0 1 -1.5707953071795862
  name "pedestrian(3)"
  shirtColor 1 0.333333 0
  pantsColor 1 0.333333 0
}
SquareManhole {
  translation -6 5.93 -0.09
  size 2 2 0.2
}
FireExtinguisher {
  hidden linearVelocity_0 1.3280878480193081e-05 0.00019502435172609982 4.391512713557705e-06
  hidden angularVelocity_0 -0.0005214681383775025 3.552028593907892e-05 -8.375587648724128e-08
  translation 7.0572936287340156 -0.005145940052998944 -0.004708812178868538
  rotation 0.21805388883662058 -0.027366213849448557 0.9755529672461526 0.03691967664196848
  name "fire extinguisher(1)"
}
FireExtinguisher {
  translation 0.11652572429349378 6.990592455565855 0.0919276820722061
  rotation 0.7120433092020936 0.5733311752697693 -0.40532171084746627 1.7729590998945521
}
ConveyorBelt {
  translation 5.21 -5.6 0
}
WoodenBox {
  translation -4.35 -0.01 2.31
  size 1 1 1
}
WoodenBox {
  translation -4.35 1.04 0.3
  name "wooden box(1)"
  size 1 1 1
}
WoodenBox {
  translation -4.35 0 0.3
  name "wooden box(2)"
  size 1 1 1
}
WoodenBox {
  translation -4.35 0 0.3
  name "wooden box(3)"
  size 1 1 1
}
WoodenBox {
  translation -1.42 0 0.3
  name "wooden box(7)"
  size 1 1 1
}
WoodenBox {
  translation 0.14 -6.33 0.8
  name "wooden box(10)"
  size 1 1 1
}
WoodenBox {
  translation 0.63 -4.73 0.78
  name "wooden box(11)"
  size 1 1 1
}
WoodenBox {
  translation -0.71 -5.19 0.76
  name "wooden box(12)"
  size 1 1 1
}
WoodenBox {
  translation -1.42 2.54 0.3
  name "wooden box(8)"
  size 1 1 1
}
WoodenBox {
  translation 0.84 1.46 0.3
  name "wooden box(9)"
  size 1 1 1
}
WoodenBox {
  translation -4.34 0.01 1.29
  name "wooden box(4)"
  size 1 1 1
}
WoodenBox {
  translation -4.37 1.04 1.31
  name "wooden box(5)"
  size 1 1 1
}
WoodenBox {
  translation -5.44 0 2.31
  name "wooden box(6)"
  size 1 1 1
}
WoodenBox {
  translation -5.44 1.08 1.31
  name "wooden box(13)"
  size 1 1 1
}
WoodenBox {
  translation -5.44 0 1.31
  name "wooden box(14)"
  size 1 1 1
}
WoodenBox {
  translation -5.44 1.06 2.31
  name "wooden box(15)"
  size 1 1 1
}
WoodenBox {
  translation -5.44 0 0.3
  name "wooden box(16)"
  size 1 1 1
}
WoodenBox {
  translation -5.44 1.11 0.3
  name "wooden box(17)"
  size 1 1 1
}
Wall {
  translation -7.36 0 0
  size 0.3 14.9 3
}
Wall {
  translation 7.32 0.01 0
  name "wall(1)"
  size 0.3 14.9 3
}
Wall {
  translation -0.0399945 -7.31 0
  rotation 0 0 1 -1.5707953071795862
  name "wall(2)"
  size 0.3 14.4 3
}
Wall {
  translation -0.0400099 7.35 0
  rotation 0 0 1 -1.5707953071795862
  name "wall(3)"
  size 0.3 14.9 3
}
SmallValve {
  hidden linearVelocity_1 -9.414482025505751e-22 8.109306443964214e-24 -1.1635301404311231e-11
  hidden angularVelocity_1 1.162092250366096e-12 6.383045255957684e-13 -3.182020799521845e-20
  translation -7.15 3.01 0.097
}
PlatformCart {
  translation -5.759825078936361 -1.6300000170988294 -0.003007540201861003
  rotation 0.0015996326479689015 -0.9999938705399529 0.003114491598212716 0.001320571236914966
}
WoodenPallet {
  translation 0 -5.61 0
  size 3 3 0.3
}
Cabinet {
  translation 7.13 3.08 0
  rotation 0 0 1 3.14159
  depth 1
}
Cabinet {
  translation 7.13 4.18 0
  rotation 0 0 1 3.14159
  name "cabinet(1)"
  depth 1
}
PlasticCrate {
  translation 3.8 6.58 0
  size 1 1 1
}
PlasticCrate {
  translation 3.8 6.58 0
  name "plastic crate(2)"
  size 0.95 0.95 0.95
}
PlasticCrate {
  translation 5.03 6.58 0
  name "plastic crate(1)"
  size 1 1 1
}
Robot {
  name "Ros2Supervisor"
  controller "<extern>"
  supervisor TRUE
}
Robot {
  translation -4.13019 4.7544 0.0559975
  rotation 1 0 0 4.692820414042842e-06
  children [
    GPS {
    }
    InertialUnit {
      translation -0.08535 0 -0.04
      rotation 1 0 0 3.14159
      name "my_imu"
    }
    Gyro {
      translation -0.085 0 -0.04
      rotation 1 0 0 3.14159
      lookupTable [
        -1000 -1000 0.005
        1000 1000 0.005
      ]
    }
    Accelerometer {
      translation -0.085 0 -0.04
      rotation 1 0 0 3.14159
      lookupTable [
        -1000 -1000 0.01
        1000 1000 0.01
      ]
    }
    Shape {
      appearance DEF white PBRAppearance {
        roughness 1
        metalness 0
      }
      geometry Box {
        size 0.31 0.22 0.08
      }
    }
    HingeJoint {
      jointParameters HingeJointParameters {
        axis 0 1 0
        anchor -0.08535 -0.125 -0.02105
      }
      device [
        RotationalMotor {
          name "joint_br"
          maxVelocity 17.29
          maxTorque 5
        }
        PositionSensor {
          name "joint_br_sensor"
          resolution 0.00385
        }
      ]
      endPoint Solid {
        translation -0.08535 -0.125 -0.02105
        rotation 0 1 0 0
        children [
          Pose {
            rotation 1 0 0 1.5708
            children [
              Shape {
                appearance DEF blue PBRAppearance {
                  baseColor 0 0 1
                  roughness 1
                  metalness 0
                }
                geometry Cylinder {
                  height 0.0255
                  radius 0.0347
                }
              }
            ]
          }
        ]
        name "link_br"
        boundingObject Pose {
          rotation 1 0 0 1.5708
          children [
            Sphere {
              radius 0.0347
            }
          ]
        }
        physics Physics {
          density -1
          mass 0.2355
          centerOfMass [
            0 0 0
          ]
          inertiaMatrix [
            8.354e-05 0.00014178 8.354e-05
            0 0 0
          ]
        }
      }
    }
    HingeJoint {
      jointParameters HingeJointParameters {
        axis 0 1 0
        anchor -0.08535 0.125 -0.02105
      }
      device [
        RotationalMotor {
          name "joint_bl"
          maxVelocity 17.29
          maxTorque 5
        }
        PositionSensor {
          name "joint_bl_sensor"
          resolution 0.00385
        }
      ]
      endPoint Solid {
        translation -0.08535 0.125 -0.02105
        rotation 0 1 0 0
        children [
          Pose {
            rotation 1 0 0 1.5708
            children [
              Shape {
                appearance PBRAppearance {
                  baseColor 0.5 0.5 0.5
                  roughness 1
                  metalness 0
                }
                geometry Cylinder {
                  height 0.0255
                  radius 0.0347
                }
              }
            ]
          }
        ]
        name "link_bl"
        boundingObject Pose {
          rotation 1 0 0 1.5708
          children [
            Sphere {
              radius 0.0347
            }
          ]
        }
        physics Physics {
          density -1
          mass 0.2355
          centerOfMass [
            0 0 0
          ]
          inertiaMatrix [
            8.354e-05 0.00014178 8.354e-05
            0 0 0
          ]
        }
      }
    }
    Solid {
      translation 0.0965 0 -0.048
      children [
        Solid {
          children [
            Shape {
              appearance DEF grey PBRAppearance {
                baseColor 0.5 0.5 0.5
                roughness 1
                metalness 0
              }
              geometry Sphere {
                radius 0.007995
              }
            }
          ]
          name "link_front"
          contactMaterial "frictionless_caster"
          boundingObject Sphere {
            radius 0.007995
          }
          physics Physics {
            density -1
            mass 0.05
            centerOfMass [
              0 0 0
            ]
            inertiaMatrix [
              1e-06 1e-06 1e-06
              0 0 0
            ]
          }
        }
      ]
      name "caster_swivel"
      physics Physics {
        density -1
        mass 0.001
        centerOfMass [
          0 0 0
        ]
        inertiaMatrix [
          1e-06 1e-06 1e-06
          0 0 0
        ]
      }
    }
    Solid {
      translation 0 0 0.04
      children [
        Pose {
          translation 0 0 0.02425
          children [
            Shape {
              appearance DEF dark_grey PBRAppearance {
                baseColor 0.2 0.2 0.2
                roughness 1
                metalness 0
              }
              geometry Cylinder {
                height 0.0485
                radius 0.0125
              }
            }
          ]
        }
        Lidar {
          name "webots_lidar"
          horizontalResolution 360
          fieldOfView 6.28318
          numberOfLayers 1
          minRange 0.12
          maxRange 3.5
          noise 0.03
          resolution 0.001
        }
      ]
      name "lidar_link"
      boundingObject Pose {
        translation 0 0 0.02425
        children [
          Cylinder {
            height 0.0485
            radius 0.0125
          }
        ]
      }
      physics Physics {
        density -1
        mass 0.052
        centerOfMass [
          0 0 0
        ]
        inertiaMatrix [
          4e-06 4e-06 4e-06
          0 0 0
        ]
      }
    }
    Solid {
      translation 0.1595 0 0.00364
      rotation -0.589061186241443 0.5531851748986483 -0.589061186241443 2.021141
      children [
        Shape {
          appearance DEF red PBRAppearance {
            baseColor 1 0 0
            roughness 1
            metalness 0
          }
          geometry Box {
            size 0.0045 0.025 0.023
          }
        }
        Pose {
          rotation 0.5773502691896258 -0.5773502691896258 0.5773502691896258 2.094395
          children [
            Camera {
              name "my_webots_camera"
              fieldOfView 1.047
              width 640
              height 480
            }
          ]
        }
      ]
      name "camera_link"
      physics Physics {
        density -1
        mass 0.004
        centerOfMass [
          0 0 0
        ]
        inertiaMatrix [
          3e-07 2e-07 2e-07
          0 0 0
        ]
      }
    }
  ]
  name "robot_a"
  boundingObject Box {
    size 0.31 0.22 0.08
  }
  physics Physics {
    density -1
    mass 1.54074
    centerOfMass [
      0 0 0
    ]
    inertiaMatrix [
      0.007512 0.014051 0.019808
      0 0 0
    ]
  }
  controller "<extern>"
}
